<robot name = "robot">
    <link name="Torso">
        <inertial>
            <origin xyz="0 0 1" rpy="0 0 0"/>
            <mass value="1" />
            <inertia ixx="100" ixy="0" ixz="0" iyy="100" iyz="0" izz="100" />
        </inertial>
        <visual>
            <origin xyz="0 0 1" rpy="0 0 0"/>
            <geometry>
                <box size="1 1 1" />
            </geometry>
            <material name="Cyan">
                <color rgba="0 1.0 1.0 1.0"/>
            </material>
        </visual>
        <collision>
            <origin xyz="0 0 1" rpy="0 0 0"/>
            <geometry>
                <box size="1 1 1" />
            </geometry>
        </collision>
    </link>
    <joint name="Torso_FrontLeg" type="revolute">
       <parent link="Torso"/>
       <child  link="FrontLeg"/>
       <origin rpy="0 0 0" xyz="0.25 0.5 1" />
     <axis xyz="1 0 0"/>
       <limit effort="0.0" lower="-3.14159" upper="3.14159" velocity="0.0"/>
    </joint>
    <link name="FrontLeg">
        <inertial>
            <origin xyz="0 0.5 0" rpy="0 0 0"/>
            <mass value="1" />
            <inertia ixx="100" ixy="0" ixz="0" iyy="100" iyz="0" izz="100" />
        </inertial>
        <visual>
            <origin xyz="0 0.5 0" rpy="0 0 0"/>
            <geometry>
                <box size="0.2 1 0.2" />
            </geometry>
            <material name="Cyan">
                <color rgba="0 1.0 1.0 1.0"/>
            </material>
        </visual>
        <collision>
            <origin xyz="0 0.5 0" rpy="0 0 0"/>
            <geometry>
                <box size="0.2 1 0.2" />
            </geometry>
        </collision>
    </link>
    <joint name="Torso_BackLeg" type="revolute">
       <parent link="Torso"/>
       <child  link="BackLeg"/>
       <origin rpy="0 0 0" xyz="0.25 -0.5 1" />
     <axis xyz="1 0 0"/>
       <limit effort="0.0" lower="-3.14159" upper="3.14159" velocity="0.0"/>
    </joint>
    <link name="BackLeg">
        <inertial>
            <origin xyz="0 -0.5 0" rpy="0 0 0"/>
            <mass value="1" />
            <inertia ixx="100" ixy="0" ixz="0" iyy="100" iyz="0" izz="100" />
        </inertial>
        <visual>
            <origin xyz="0 -0.5 0" rpy="0 0 0"/>
            <geometry>
                <box size="0.2 1 0.2" />
            </geometry>
            <material name="Cyan">
                <color rgba="0 1.0 1.0 1.0"/>
            </material>
        </visual>
        <collision>
            <origin xyz="0 -0.5 0" rpy="0 0 0"/>
            <geometry>
                <box size="0.2 1 0.2" />
            </geometry>
        </collision>
    </link>
    <joint name="Torso_LeftLeg" type="revolute">
       <parent link="Torso"/>
       <child  link="LeftLeg"/>
       <origin rpy="0 0 0" xyz="0.5 0.25 1" />
     <axis xyz="1 0 0"/>
       <limit effort="0.0" lower="-3.14159" upper="3.14159" velocity="0.0"/>
    </joint>
    <link name="LeftLeg">
        <inertial>
            <origin xyz="0.5 0 0" rpy="0 0 0"/>
            <mass value="1" />
            <inertia ixx="100" ixy="0" ixz="0" iyy="100" iyz="0" izz="100" />
        </inertial>
        <visual>
            <origin xyz="0.5 0 0" rpy="0 0 0"/>
            <geometry>
                <box size="1 0.2 0.2" />
            </geometry>
            <material name="Cyan">
                <color rgba="0 1.0 1.0 1.0"/>
            </material>
        </visual>
        <collision>
            <origin xyz="0.5 0 0" rpy="0 0 0"/>
            <geometry>
                <box size="1 0.2 0.2" />
            </geometry>
        </collision>
    </link>
    <joint name="Torso_RightLeg" type="revolute">
       <parent link="Torso"/>
       <child  link="RightLeg"/>
       <origin rpy="0 0 0" xyz="-0.5 0.25 1" />
     <axis xyz="1 0 0"/>
       <limit effort="0.0" lower="-3.14159" upper="3.14159" velocity="0.0"/>
    </joint>
    <link name="RightLeg">
        <inertial>
            <origin xyz="-0.5 0 0" rpy="0 0 0"/>
            <mass value="1" />
            <inertia ixx="100" ixy="0" ixz="0" iyy="100" iyz="0" izz="100" />
        </inertial>
        <visual>
            <origin xyz="-0.5 0 0" rpy="0 0 0"/>
            <geometry>
                <box size="1 0.2 0.2" />
            </geometry>
            <material name="Cyan">
                <color rgba="0 1.0 1.0 1.0"/>
            </material>
        </visual>
        <collision>
            <origin xyz="-0.5 0 0" rpy="0 0 0"/>
            <geometry>
                <box size="1 0.2 0.2" />
            </geometry>
        </collision>
    </link>
    <joint name="Torso_FrontLeg1" type="revolute">
       <parent link="Torso"/>
       <child  link="FrontLeg1"/>
       <origin rpy="0 0 0" xyz="-0.25 0.5 1" />
     <axis xyz="1 0 0"/>
       <limit effort="0.0" lower="-3.14159" upper="3.14159" velocity="0.0"/>
    </joint>
    <link name="FrontLeg1">
        <inertial>
            <origin xyz="0 0.5 0" rpy="0 0 0"/>
            <mass value="1" />
            <inertia ixx="100" ixy="0" ixz="0" iyy="100" iyz="0" izz="100" />
        </inertial>
        <visual>
            <origin xyz="0 0.5 0" rpy="0 0 0"/>
            <geometry>
                <box size="0.2 1 0.2" />
            </geometry>
            <material name="Cyan">
                <color rgba="0 1.0 1.0 1.0"/>
            </material>
        </visual>
        <collision>
            <origin xyz="0 0.5 0" rpy="0 0 0"/>
            <geometry>
                <box size="0.2 1 0.2" />
            </geometry>
        </collision>
    </link>
    <joint name="Torso_BackLeg1" type="revolute">
       <parent link="Torso"/>
       <child  link="BackLeg1"/>
       <origin rpy="0 0 0" xyz="-0.25 -0.5 1" />
     <axis xyz="1 0 0"/>
       <limit effort="0.0" lower="-3.14159" upper="3.14159" velocity="0.0"/>
    </joint>
    <link name="BackLeg1">
        <inertial>
            <origin xyz="0 -0.5 0" rpy="0 0 0"/>
            <mass value="1" />
            <inertia ixx="100" ixy="0" ixz="0" iyy="100" iyz="0" izz="100" />
        </inertial>
        <visual>
            <origin xyz="0 -0.5 0" rpy="0 0 0"/>
            <geometry>
                <box size="0.2 1 0.2" />
            </geometry>
            <material name="Cyan">
                <color rgba="0 1.0 1.0 1.0"/>
            </material>
        </visual>
        <collision>
            <origin xyz="0 -0.5 0" rpy="0 0 0"/>
            <geometry>
                <box size="0.2 1 0.2" />
            </geometry>
        </collision>
    </link>
    <joint name="Torso_LeftLeg1" type="revolute">
       <parent link="Torso"/>
       <child  link="LeftLeg1"/>
       <origin rpy="0 0 0" xyz="0.5 -0.25 1" />
     <axis xyz="1 0 0"/>
       <limit effort="0.0" lower="-3.14159" upper="3.14159" velocity="0.0"/>
    </joint>
    <link name="LeftLeg1">
        <inertial>
            <origin xyz="0.5 0 0" rpy="0 0 0"/>
            <mass value="1" />
            <inertia ixx="100" ixy="0" ixz="0" iyy="100" iyz="0" izz="100" />
        </inertial>
        <visual>
            <origin xyz="0.5 0 0" rpy="0 0 0"/>
            <geometry>
                <box size="1 0.2 0.2" />
            </geometry>
            <material name="Cyan">
                <color rgba="0 1.0 1.0 1.0"/>
            </material>
        </visual>
        <collision>
            <origin xyz="0.5 0 0" rpy="0 0 0"/>
            <geometry>
                <box size="1 0.2 0.2" />
            </geometry>
        </collision>
    </link>
    <joint name="Torso_RightLeg1" type="revolute">
       <parent link="Torso"/>
       <child  link="RightLeg1"/>
       <origin rpy="0 0 0" xyz="-0.5 -0.25 1" />
     <axis xyz="1 0 0"/>
       <limit effort="0.0" lower="-3.14159" upper="3.14159" velocity="0.0"/>
    </joint>
    <link name="RightLeg1">
        <inertial>
            <origin xyz="-0.5 0 0" rpy="0 0 0"/>
            <mass value="1" />
            <inertia ixx="100" ixy="0" ixz="0" iyy="100" iyz="0" izz="100" />
        </inertial>
        <visual>
            <origin xyz="-0.5 0 0" rpy="0 0 0"/>
            <geometry>
                <box size="1 0.2 0.2" />
            </geometry>
            <material name="Cyan">
                <color rgba="0 1.0 1.0 1.0"/>
            </material>
        </visual>
        <collision>
            <origin xyz="-0.5 0 0" rpy="0 0 0"/>
            <geometry>
                <box size="1 0.2 0.2" />
            </geometry>
        </collision>
    </link>
    <joint name="FrontLeg_LowerFrontLeg" type="revolute">
       <parent link="FrontLeg"/>
       <child  link="LowerFrontLeg"/>
       <origin rpy="0 0 0" xyz="0 1 0" />
     <axis xyz="1 0 0"/>
       <limit effort="0.0" lower="-3.14159" upper="3.14159" velocity="0.0"/>
    </joint>
    <link name="LowerFrontLeg">
        <inertial>
            <origin xyz="0 0 -0.5" rpy="0 0 0"/>
            <mass value="1" />
            <inertia ixx="100" ixy="0" ixz="0" iyy="100" iyz="0" izz="100" />
        </inertial>
        <visual>
            <origin xyz="0 0 -0.5" rpy="0 0 0"/>
            <geometry>
                <box size="0.2 0.2 1" />
            </geometry>
            <material name="Cyan">
                <color rgba="0 1.0 1.0 1.0"/>
            </material>
        </visual>
        <collision>
            <origin xyz="0 0 -0.5" rpy="0 0 0"/>
            <geometry>
                <box size="0.2 0.2 1" />
            </geometry>
        </collision>
    </link>
    <joint name="BackLeg_LowerBackLeg" type="revolute">
       <parent link="BackLeg"/>
       <child  link="LowerBackLeg"/>
       <origin rpy="0 0 0" xyz="0 -1 0" />
     <axis xyz="1 0 0"/>
       <limit effort="0.0" lower="-3.14159" upper="3.14159" velocity="0.0"/>
    </joint>
    <link name="LowerBackLeg">
        <inertial>
            <origin xyz="0 0 -0.5" rpy="0 0 0"/>
            <mass value="1" />
            <inertia ixx="100" ixy="0" ixz="0" iyy="100" iyz="0" izz="100" />
        </inertial>
        <visual>
            <origin xyz="0 0 -0.5" rpy="0 0 0"/>
            <geometry>
                <box size="0.2 0.2 1" />
            </geometry>
            <material name="Cyan">
                <color rgba="0 1.0 1.0 1.0"/>
            </material>
        </visual>
        <collision>
            <origin xyz="0 0 -0.5" rpy="0 0 0"/>
            <geometry>
                <box size="0.2 0.2 1" />
            </geometry>
        </collision>
    </link>
    <joint name="LeftLeg_LowerLeftLeg" type="revolute">
       <parent link="LeftLeg"/>
       <child  link="LowerLeftLeg"/>
       <origin rpy="0 0 0" xyz="1 0 0" />
     <axis xyz="1 0 0"/>
       <limit effort="0.0" lower="-3.14159" upper="3.14159" velocity="0.0"/>
    </joint>
    <link name="LowerLeftLeg">
        <inertial>
            <origin xyz="0 0 -0.5" rpy="0 0 0"/>
            <mass value="1" />
            <inertia ixx="100" ixy="0" ixz="0" iyy="100" iyz="0" izz="100" />
        </inertial>
        <visual>
            <origin xyz="0 0 -0.5" rpy="0 0 0"/>
            <geometry>
                <box size="0.2 0.2 1" />
            </geometry>
            <material name="Cyan">
                <color rgba="0 1.0 1.0 1.0"/>
            </material>
        </visual>
        <collision>
            <origin xyz="0 0 -0.5" rpy="0 0 0"/>
            <geometry>
                <box size="0.2 0.2 1" />
            </geometry>
        </collision>
    </link>
    <joint name="RightLeg_LowerRightLeg" type="revolute">
       <parent link="RightLeg"/>
       <child  link="LowerRightLeg"/>
       <origin rpy="0 0 0" xyz="-1 0 0" />
     <axis xyz="1 0 0"/>
       <limit effort="0.0" lower="-3.14159" upper="3.14159" velocity="0.0"/>
    </joint>
    <link name="LowerRightLeg">
        <inertial>
            <origin xyz="0 0 -0.5" rpy="0 0 0"/>
            <mass value="1" />
            <inertia ixx="100" ixy="0" ixz="0" iyy="100" iyz="0" izz="100" />
        </inertial>
        <visual>
            <origin xyz="0 0 -0.5" rpy="0 0 0"/>
            <geometry>
                <box size="0.2 0.2 1" />
            </geometry>
            <material name="Cyan">
                <color rgba="0 1.0 1.0 1.0"/>
            </material>
        </visual>
        <collision>
            <origin xyz="0 0 -0.5" rpy="0 0 0"/>
            <geometry>
                <box size="0.2 0.2 1" />
            </geometry>
        </collision>
    </link>
    <joint name="FrontLeg1_LowerFrontLeg1" type="revolute">
       <parent link="FrontLeg1"/>
       <child  link="LowerFrontLeg1"/>
       <origin rpy="0 0 0" xyz="0 1 0" />
     <axis xyz="1 0 0"/>
       <limit effort="0.0" lower="-3.14159" upper="3.14159" velocity="0.0"/>
    </joint>
    <link name="LowerFrontLeg1">
        <inertial>
            <origin xyz="0 0 -0.5" rpy="0 0 0"/>
            <mass value="1" />
            <inertia ixx="100" ixy="0" ixz="0" iyy="100" iyz="0" izz="100" />
        </inertial>
        <visual>
            <origin xyz="0 0 -0.5" rpy="0 0 0"/>
            <geometry>
                <box size="0.2 0.2 1" />
            </geometry>
            <material name="Cyan">
                <color rgba="0 1.0 1.0 1.0"/>
            </material>
        </visual>
        <collision>
            <origin xyz="0 0 -0.5" rpy="0 0 0"/>
            <geometry>
                <box size="0.2 0.2 1" />
            </geometry>
        </collision>
    </link>
    <joint name="BackLeg1_LowerBackLeg1" type="revolute">
       <parent link="BackLeg1"/>
       <child  link="LowerBackLeg1"/>
       <origin rpy="0 0 0" xyz="0 -1 0" />
     <axis xyz="1 0 0"/>
       <limit effort="0.0" lower="-3.14159" upper="3.14159" velocity="0.0"/>
    </joint>
    <link name="LowerBackLeg1">
        <inertial>
            <origin xyz="0 0 -0.5" rpy="0 0 0"/>
            <mass value="1" />
            <inertia ixx="100" ixy="0" ixz="0" iyy="100" iyz="0" izz="100" />
        </inertial>
        <visual>
            <origin xyz="0 0 -0.5" rpy="0 0 0"/>
            <geometry>
                <box size="0.2 0.2 1" />
            </geometry>
            <material name="Cyan">
                <color rgba="0 1.0 1.0 1.0"/>
            </material>
        </visual>
        <collision>
            <origin xyz="0 0 -0.5" rpy="0 0 0"/>
            <geometry>
                <box size="0.2 0.2 1" />
            </geometry>
        </collision>
    </link>
    <joint name="LeftLeg1_LowerLeftLeg1" type="revolute">
       <parent link="LeftLeg1"/>
       <child  link="LowerLeftLeg1"/>
       <origin rpy="0 0 0" xyz="1 0 0" />
     <axis xyz="1 0 0"/>
       <limit effort="0.0" lower="-3.14159" upper="3.14159" velocity="0.0"/>
    </joint>
    <link name="LowerLeftLeg1">
        <inertial>
            <origin xyz="0 0 -0.5" rpy="0 0 0"/>
            <mass value="1" />
            <inertia ixx="100" ixy="0" ixz="0" iyy="100" iyz="0" izz="100" />
        </inertial>
        <visual>
            <origin xyz="0 0 -0.5" rpy="0 0 0"/>
            <geometry>
                <box size="0.2 0.2 1" />
            </geometry>
            <material name="Cyan">
                <color rgba="0 1.0 1.0 1.0"/>
            </material>
        </visual>
        <collision>
            <origin xyz="0 0 -0.5" rpy="0 0 0"/>
            <geometry>
                <box size="0.2 0.2 1" />
            </geometry>
        </collision>
    </link>
    <joint name="RightLeg1_LowerRightLeg1" type="revolute">
       <parent link="RightLeg1"/>
       <child  link="LowerRightLeg1"/>
       <origin rpy="0 0 0" xyz="-1 0 0" />
     <axis xyz="1 0 0"/>
       <limit effort="0.0" lower="-3.14159" upper="3.14159" velocity="0.0"/>
    </joint>
    <link name="LowerRightLeg1">
        <inertial>
            <origin xyz="0 0 -0.5" rpy="0 0 0"/>
            <mass value="1" />
            <inertia ixx="100" ixy="0" ixz="0" iyy="100" iyz="0" izz="100" />
        </inertial>
        <visual>
            <origin xyz="0 0 -0.5" rpy="0 0 0"/>
            <geometry>
                <box size="0.2 0.2 1" />
            </geometry>
            <material name="Cyan">
                <color rgba="0 1.0 1.0 1.0"/>
            </material>
        </visual>
        <collision>
            <origin xyz="0 0 -0.5" rpy="0 0 0"/>
            <geometry>
                <box size="0.2 0.2 1" />
            </geometry>
        </collision>
    </link>
</robot>